Traceback (most recent call last):
  File "C:\Users\msipc\AppData\Roaming\Python\Python37\site-packages\jupyter_cache\executors\utils.py", line 56, in single_nb_execution
    record_timing=False,
  File "C:\Users\msipc\AppData\Roaming\Python\Python37\site-packages\nbclient\client.py", line 1204, in execute
    return NotebookClient(nb=nb, resources=resources, km=km, **kwargs).execute()
  File "C:\Users\msipc\AppData\Roaming\Python\Python37\site-packages\nbclient\util.py", line 84, in wrapped
    return just_run(coro(*args, **kwargs))
  File "C:\Users\msipc\AppData\Roaming\Python\Python37\site-packages\nbclient\util.py", line 62, in just_run
    return loop.run_until_complete(coro)
  File "D:\ProgramData\Anaconda3\lib\asyncio\base_events.py", line 587, in run_until_complete
    return future.result()
  File "C:\Users\msipc\AppData\Roaming\Python\Python37\site-packages\nbclient\client.py", line 664, in async_execute
    cell, index, execution_count=self.code_cells_executed + 1
  File "C:\Users\msipc\AppData\Roaming\Python\Python37\site-packages\nbclient\client.py", line 965, in async_execute_cell
    await self._check_raise_for_error(cell, cell_index, exec_reply)
  File "C:\Users\msipc\AppData\Roaming\Python\Python37\site-packages\nbclient\client.py", line 862, in _check_raise_for_error
    raise CellExecutionError.from_cell_and_msg(cell, exec_reply_content)
nbclient.exceptions.CellExecutionError: An error occurred while executing the following cell:
------------------
import sklearn

print(f"scikit-learn version: {sklearn.__version__}")

from sklearn.datasets import load_iris
from sklearn.tree import (
    DecisionTreeClassifier,
    DecisionTreeRegressor,
    plot_tree,
    export_graphviz,
)
from sklearn.ensemble import RandomForestClassifier
from sklearn.model_selection import cross_val_score
------------------

[1;31m---------------------------------------------------------------------------[0m
[1;31mImportError[0m                               Traceback (most recent call last)
[1;32m<ipython-input-3-8bd6a235de4c>[0m in [0;36m<module>[1;34m[0m
[0;32m      4[0m [1;33m[0m[0m
[0;32m      5[0m [1;32mfrom[0m [0msklearn[0m[1;33m.[0m[0mdatasets[0m [1;32mimport[0m [0mload_iris[0m[1;33m[0m[1;33m[0m[0m
[1;32m----> 6[1;33m from sklearn.tree import (
[0m[0;32m      7[0m     [0mDecisionTreeClassifier[0m[1;33m,[0m[1;33m[0m[1;33m[0m[0m
[0;32m      8[0m     [0mDecisionTreeRegressor[0m[1;33m,[0m[1;33m[0m[1;33m[0m[0m

[1;31mImportError[0m: cannot import name 'plot_tree' from 'sklearn.tree' (D:\ProgramData\Anaconda3\lib\site-packages\sklearn\tree\__init__.py)
ImportError: cannot import name 'plot_tree' from 'sklearn.tree' (D:\ProgramData\Anaconda3\lib\site-packages\sklearn\tree\__init__.py)

