Traceback (most recent call last):
  File "C:\Users\msipc\AppData\Roaming\Python\Python37\site-packages\jupyter_cache\executors\utils.py", line 56, in single_nb_execution
    record_timing=False,
  File "C:\Users\msipc\AppData\Roaming\Python\Python37\site-packages\nbclient\client.py", line 1204, in execute
    return NotebookClient(nb=nb, resources=resources, km=km, **kwargs).execute()
  File "C:\Users\msipc\AppData\Roaming\Python\Python37\site-packages\nbclient\util.py", line 84, in wrapped
    return just_run(coro(*args, **kwargs))
  File "C:\Users\msipc\AppData\Roaming\Python\Python37\site-packages\nbclient\util.py", line 62, in just_run
    return loop.run_until_complete(coro)
  File "D:\ProgramData\Anaconda3\lib\asyncio\base_events.py", line 587, in run_until_complete
    return future.result()
  File "C:\Users\msipc\AppData\Roaming\Python\Python37\site-packages\nbclient\client.py", line 664, in async_execute
    cell, index, execution_count=self.code_cells_executed + 1
  File "C:\Users\msipc\AppData\Roaming\Python\Python37\site-packages\nbclient\client.py", line 965, in async_execute_cell
    await self._check_raise_for_error(cell, cell_index, exec_reply)
  File "C:\Users\msipc\AppData\Roaming\Python\Python37\site-packages\nbclient\client.py", line 862, in _check_raise_for_error
    raise CellExecutionError.from_cell_and_msg(cell, exec_reply_content)
nbclient.exceptions.CellExecutionError: An error occurred while executing the following cell:
------------------
# Generate 2 classes of linearly separable data
x_train, y_train = make_classification(
    n_samples=1000,
    n_features=2,
    n_redundant=0,
    n_informative=2,
    random_state=26,
    n_clusters_per_class=1,
)
plot_data(x_train, y_train)
------------------

[1;31m---------------------------------------------------------------------------[0m
[1;31mAttributeError[0m                            Traceback (most recent call last)
[1;32m<ipython-input-5-1b1108a63e4a>[0m in [0;36m<module>[1;34m[0m
[0;32m      8[0m     [0mn_clusters_per_class[0m[1;33m=[0m[1;36m1[0m[1;33m,[0m[1;33m[0m[1;33m[0m[0m
[0;32m      9[0m )
[1;32m---> 10[1;33m [0mplot_data[0m[1;33m([0m[0mx_train[0m[1;33m,[0m [0my_train[0m[1;33m)[0m[1;33m[0m[1;33m[0m[0m
[0m
[1;32m<ipython-input-4-b2991d7dc072>[0m in [0;36mplot_data[1;34m(x, y)[0m
[0;32m      4[0m     [0mfig[0m[1;33m,[0m [0max[0m [1;33m=[0m [0mplt[0m[1;33m.[0m[0msubplots[0m[1;33m([0m[1;33m)[0m[1;33m[0m[1;33m[0m[0m
[0;32m      5[0m     [0mscatter[0m [1;33m=[0m [0max[0m[1;33m.[0m[0mscatter[0m[1;33m([0m[0mx[0m[1;33m[[0m[1;33m:[0m[1;33m,[0m [1;36m0[0m[1;33m][0m[1;33m,[0m [0mx[0m[1;33m[[0m[1;33m:[0m[1;33m,[0m [1;36m1[0m[1;33m][0m[1;33m,[0m [0mc[0m[1;33m=[0m[0my[0m[1;33m,[0m [0ms[0m[1;33m=[0m[1;36m40[0m[1;33m,[0m [0mcmap[0m[1;33m=[0m[0mplt[0m[1;33m.[0m[0mcm[0m[1;33m.[0m[0mRdYlBu[0m[1;33m)[0m[1;33m[0m[1;33m[0m[0m
[1;32m----> 6[1;33m     legend1 = ax.legend(*scatter.legend_elements(),
[0m[0;32m      7[0m                     loc="lower right", title="Classes")
[0;32m      8[0m     [0max[0m[1;33m.[0m[0madd_artist[0m[1;33m([0m[0mlegend1[0m[1;33m)[0m[1;33m[0m[1;33m[0m[0m

[1;31mAttributeError[0m: 'PathCollection' object has no attribute 'legend_elements'
AttributeError: 'PathCollection' object has no attribute 'legend_elements'

